Loaded module: python3/3.6.2
Loaded module: cuda/8.0
Loaded module: cudnn/v7.0-prod-cuda8
Traceback (most recent call last):
  File "/zhome/95/8/135203/.local/lib/python3.6/site-packages/torch/utils/data/dataloader.py", line 724, in _try_get_data
    data = self._data_queue.get(timeout=timeout)
  File "/appl/python/3.6.2/lib/python3.6/multiprocessing/queues.py", line 104, in get
    if timeout < 0 or not self._poll(timeout):
  File "/appl/python/3.6.2/lib/python3.6/multiprocessing/connection.py", line 257, in poll
    return self._poll(timeout)
  File "/appl/python/3.6.2/lib/python3.6/multiprocessing/connection.py", line 414, in _poll
    r = wait([self], timeout)
  File "/appl/python/3.6.2/lib/python3.6/multiprocessing/connection.py", line 911, in wait
    ready = selector.select(timeout)
  File "/appl/python/3.6.2/lib/python3.6/selectors.py", line 376, in select
    fd_event_list = self._poll.poll(timeout)
  File "/zhome/95/8/135203/.local/lib/python3.6/site-packages/torch/utils/data/_utils/signal_handling.py", line 66, in handler
    _error_if_any_worker_fails()
RuntimeError: DataLoader worker (pid 23000) is killed by signal: Killed. 

During handling of the above exception, another exception occurred:

Traceback (most recent call last):
  File "python/train.py", line 370, in <module>
    val(start_epoch)  # show the accuracy before training
  File "python/train.py", line 315, in val
    for iter, batch in enumerate(val_loader):
  File "/zhome/95/8/135203/.local/lib/python3.6/site-packages/torch/utils/data/dataloader.py", line 804, in __next__
    idx, data = self._get_data()
  File "/zhome/95/8/135203/.local/lib/python3.6/site-packages/torch/utils/data/dataloader.py", line 771, in _get_data
    success, data = self._try_get_data()
  File "/zhome/95/8/135203/.local/lib/python3.6/site-packages/torch/utils/data/dataloader.py", line 737, in _try_get_data
    raise RuntimeError('DataLoader worker (pid(s) {}) exited unexpectedly'.format(pids_str))
RuntimeError: DataLoader worker (pid(s) 22989, 22994, 22996, 23000) exited unexpectedly
